
--------------------------------Current date and time = 2023-10-22 18:19:13.390313
Traceback (most recent call last):
  File "C:\Users\Public\code\automate-with-python\011-debugging\001-2-traceback.py", line 8, in <module>
    raise Exception('Allan error message')
Exception: Allan error message

--------------------------------Current date and time = 2023-10-22 18:19:17.425344
Traceback (most recent call last):
  File "C:\Users\Public\code\automate-with-python\011-debugging\001-2-traceback.py", line 8, in <module>
    raise Exception('Allan error message')
Exception: Allan error message

--------------------------------Current date and time = 2023-10-22 18:19:26.751097
Traceback (most recent call last):
  File "C:\Users\Public\code\automate-with-python\011-debugging\001-2-traceback.py", line 8, in <module>
    raise Exception('Allan error message')
Exception: Allan error message

--------------------------------Current date and time = 2023-10-23 19:40:10.364882
Traceback (most recent call last):
  File "C:\Users\Public\code\automate-with-python\011-debugging\001-2-traceback.py", line 8, in <module>
    raise Exception('Allan error message')
Exception: Allan error message

--------------------------------Current date and time = 2023-10-23 19:40:23.866245
Traceback (most recent call last):
  File "C:\Users\Public\code\automate-with-python\011-debugging\001-2-traceback.py", line 8, in <module>
    raise Exception('Allan error message')
Exception: Allan error message

--------------------------------Current date and time = 2023-10-23 19:40:56.282468
Traceback (most recent call last):
  File "C:\Users\Public\code\automate-with-python\011-debugging\001-2-traceback.py", line 8, in <module>
    raise Exception('Allan error message')
Exception: Allan error message

--------------------------------Current date and time = 2023-10-23 19:41:09.863278
Traceback (most recent call last):
  File "C:\Users\Public\code\automate-with-python\011-debugging\001-2-traceback.py", line 8, in <module>
    raise Exception('Allan error message')
Exception: Allan error message

--------------------------------Current date and time = 2023-10-23 19:41:19.776399
Traceback (most recent call last):
  File "C:\Users\Public\code\automate-with-python\011-debugging\001-2-traceback.py", line 8, in <module>
    raise Exception('Allan error message')
Exception: Allan error message
